Traceback (most recent call last):
  File "C:\Users\gepap\Anaconda3\Lib\site-packages\pandas\core\indexes\base.py", line 3805, in get_loc
    return self._engine.get_loc(casted_key)
           ^^^^^^^^^^^^^^^^^^^^^^^^^^^^^^^^
  File "index.pyx", line 167, in pandas._libs.index.IndexEngine.get_loc
  File "index.pyx", line 196, in pandas._libs.index.IndexEngine.get_loc
  File "pandas\\_libs\\hashtable_class_helper.pxi", line 7081, in pandas._libs.hashtable.PyObjectHashTable.get_item
  File "pandas\\_libs\\hashtable_class_helper.pxi", line 7089, in pandas._libs.hashtable.PyObjectHashTable.get_item
KeyError: 'price'

The above exception was the direct cause of the following exception:

Traceback (most recent call last):
  File "C:\Users\gepap\Desktop\Thesis\RL Agent\main.py", line 64, in <module>
    main()
  File "C:\Users\gepap\Desktop\Thesis\RL Agent\main.py", line 40, in main
    base_env = RenewableInvestmentEnv(data)
               ^^^^^^^^^^^^^^^^^^^^^^^^^^^^
  File "C:\Users\gepap\Desktop\Thesis\RL Agent\RenewableInvestmentEnv.py", line 28, in __init__
    self.reset()
  File "C:\Users\gepap\Desktop\Thesis\RL Agent\RenewableInvestmentEnv.py", line 40, in reset
    return self._get_obs(), {}
           ^^^^^^^^^^^^^^^
  File "C:\Users\gepap\Desktop\Thesis\RL Agent\RenewableInvestmentEnv.py", line 48, in _get_obs
    row['price'] / 500,
    ~~~^^^^^^^^^^^^^^^^
  File "C:\Users\gepap\Anaconda3\Lib\site-packages\pandas\core\series.py", line 1121, in __getitem__
    return self._get_value(key)
           ^^^^^^^^^^^^^^^^^^^^
  File "C:\Users\gepap\Anaconda3\Lib\site-packages\pandas\core\series.py", line 1237, in _get_value
    loc = self.index.get_loc(label)
          ^^^^^^^^^^^^^^^^^^^^^^^^^
  File "C:\Users\gepap\Anaconda3\Lib\site-packages\pandas\core\indexes\base.py", line 3812, in get_loc
    raise KeyError(key) from err
KeyError: 'price'
